2025-01-22 09:19:28,231 (59772/MainThread) pgcli.main INFO - No default pager found in environment. Using os default pager
2025-01-22 09:19:28,231 (59772/MainThread) pgcli.main WARNING - import keyring failed: ModuleNotFoundError("No module named 'keyring'").
2025-01-22 09:19:30,264 (59772/MainThread) pgcli.main ERROR - traceback: 'Traceback (most recent call last):\n  File "/usr/lib/python3.13/site-packages/pgcli/main.py", line 729, in connect\n    pgexecute = PGExecute(\n        database,\n    ...<6 lines>...\n        **kwargs,\n    )\n  File "/usr/lib/python3.13/site-packages/pgcli/pgexecute.py", line 184, in __init__\n    self.connect(database, user, password, host, port, dsn, **kwargs)\n    ~~~~~~~~~~~~^^^^^^^^^^^^^^^^^^^^^^^^^^^^^^^^^^^^^^^^^^^^^^^^^^^^^\n  File "/usr/lib/python3.13/site-packages/pgcli/pgexecute.py", line 233, in connect\n    conn = psycopg.connect(conn_info)\n  File "/usr/lib/python3.13/site-packages/psycopg/connection.py", line 119, in connect\n    raise last_ex.with_traceback(None)\npsycopg.OperationalError: connection failed: connection to server at "127.0.0.1", port 5432 failed: fe_sendauth: no password supplied\n\nDuring handling of the above exception, another exception occurred:\n\nTraceback (most recent call last):\n  File "/usr/lib/python3.13/site-packages/pgcli/main.py", line 747, in connect\n    pgexecute = PGExecute(\n        database,\n    ...<6 lines>...\n        **kwargs,\n    )\n  File "/usr/lib/python3.13/site-packages/pgcli/pgexecute.py", line 184, in __init__\n    self.connect(database, user, password, host, port, dsn, **kwargs)\n    ~~~~~~~~~~~~^^^^^^^^^^^^^^^^^^^^^^^^^^^^^^^^^^^^^^^^^^^^^^^^^^^^^\n  File "/usr/lib/python3.13/site-packages/pgcli/pgexecute.py", line 233, in connect\n    conn = psycopg.connect(conn_info)\n  File "/usr/lib/python3.13/site-packages/psycopg/connection.py", line 119, in connect\n    raise last_ex.with_traceback(None)\npsycopg.OperationalError: connection failed: connection to server at "127.0.0.1", port 5432 failed: FATAL:  database "ny_taxi" does not exist\n'
2025-01-22 09:19:59,884 (59971/MainThread) pgcli.main INFO - No default pager found in environment. Using os default pager
2025-01-22 09:19:59,884 (59971/MainThread) pgcli.main WARNING - import keyring failed: ModuleNotFoundError("No module named 'keyring'").
2025-01-22 09:20:02,015 (59971/MainThread) pgcli.main ERROR - traceback: 'Traceback (most recent call last):\n  File "/usr/lib/python3.13/site-packages/pgcli/main.py", line 729, in connect\n    pgexecute = PGExecute(\n        database,\n    ...<6 lines>...\n        **kwargs,\n    )\n  File "/usr/lib/python3.13/site-packages/pgcli/pgexecute.py", line 184, in __init__\n    self.connect(database, user, password, host, port, dsn, **kwargs)\n    ~~~~~~~~~~~~^^^^^^^^^^^^^^^^^^^^^^^^^^^^^^^^^^^^^^^^^^^^^^^^^^^^^\n  File "/usr/lib/python3.13/site-packages/pgcli/pgexecute.py", line 233, in connect\n    conn = psycopg.connect(conn_info)\n  File "/usr/lib/python3.13/site-packages/psycopg/connection.py", line 119, in connect\n    raise last_ex.with_traceback(None)\npsycopg.OperationalError: connection failed: connection to server at "127.0.0.1", port 5432 failed: fe_sendauth: no password supplied\n\nDuring handling of the above exception, another exception occurred:\n\nTraceback (most recent call last):\n  File "/usr/lib/python3.13/site-packages/pgcli/main.py", line 747, in connect\n    pgexecute = PGExecute(\n        database,\n    ...<6 lines>...\n        **kwargs,\n    )\n  File "/usr/lib/python3.13/site-packages/pgcli/pgexecute.py", line 184, in __init__\n    self.connect(database, user, password, host, port, dsn, **kwargs)\n    ~~~~~~~~~~~~^^^^^^^^^^^^^^^^^^^^^^^^^^^^^^^^^^^^^^^^^^^^^^^^^^^^^\n  File "/usr/lib/python3.13/site-packages/pgcli/pgexecute.py", line 233, in connect\n    conn = psycopg.connect(conn_info)\n  File "/usr/lib/python3.13/site-packages/psycopg/connection.py", line 119, in connect\n    raise last_ex.with_traceback(None)\npsycopg.OperationalError: connection failed: connection to server at "127.0.0.1", port 5432 failed: FATAL:  database "ny_taxi" does not exist\n'
2025-01-22 09:21:37,042 (60244/MainThread) pgcli.main INFO - No default pager found in environment. Using os default pager
2025-01-22 09:21:37,042 (60244/MainThread) pgcli.main WARNING - import keyring failed: ModuleNotFoundError("No module named 'keyring'").
2025-01-22 09:26:00,708 (60908/MainThread) pgcli.main INFO - No default pager found in environment. Using os default pager
2025-01-22 09:26:00,708 (60908/MainThread) pgcli.main WARNING - import keyring failed: ModuleNotFoundError("No module named 'keyring'").
2025-01-22 09:26:02,634 (60908/MainThread) pgcli.main ERROR - traceback: 'Traceback (most recent call last):\n  File "/usr/lib/python3.13/site-packages/pgcli/main.py", line 729, in connect\n    pgexecute = PGExecute(\n        database,\n    ...<6 lines>...\n        **kwargs,\n    )\n  File "/usr/lib/python3.13/site-packages/pgcli/pgexecute.py", line 184, in __init__\n    self.connect(database, user, password, host, port, dsn, **kwargs)\n    ~~~~~~~~~~~~^^^^^^^^^^^^^^^^^^^^^^^^^^^^^^^^^^^^^^^^^^^^^^^^^^^^^\n  File "/usr/lib/python3.13/site-packages/pgcli/pgexecute.py", line 233, in connect\n    conn = psycopg.connect(conn_info)\n  File "/usr/lib/python3.13/site-packages/psycopg/connection.py", line 119, in connect\n    raise last_ex.with_traceback(None)\npsycopg.OperationalError: connection failed: connection to server at "127.0.0.1", port 5432 failed: fe_sendauth: no password supplied\n\nDuring handling of the above exception, another exception occurred:\n\nTraceback (most recent call last):\n  File "/usr/lib/python3.13/site-packages/pgcli/main.py", line 747, in connect\n    pgexecute = PGExecute(\n        database,\n    ...<6 lines>...\n        **kwargs,\n    )\n  File "/usr/lib/python3.13/site-packages/pgcli/pgexecute.py", line 184, in __init__\n    self.connect(database, user, password, host, port, dsn, **kwargs)\n    ~~~~~~~~~~~~^^^^^^^^^^^^^^^^^^^^^^^^^^^^^^^^^^^^^^^^^^^^^^^^^^^^^\n  File "/usr/lib/python3.13/site-packages/pgcli/pgexecute.py", line 233, in connect\n    conn = psycopg.connect(conn_info)\n  File "/usr/lib/python3.13/site-packages/psycopg/connection.py", line 119, in connect\n    raise last_ex.with_traceback(None)\npsycopg.OperationalError: connection failed: connection to server at "127.0.0.1", port 5432 failed: FATAL:  database "ny_taxi" does not exist\n'
2025-01-22 09:27:26,473 (61256/MainThread) pgcli.main INFO - No default pager found in environment. Using os default pager
2025-01-22 09:27:26,473 (61256/MainThread) pgcli.main WARNING - import keyring failed: ModuleNotFoundError("No module named 'keyring'").
2025-01-25 11:50:16,403 (164226/MainThread) pgcli.main INFO - No default pager found in environment. Using os default pager
2025-01-25 11:50:16,404 (164226/MainThread) pgcli.main WARNING - import keyring failed: ModuleNotFoundError("No module named 'keyring'").
2025-01-25 11:50:16,406 (164226/MainThread) pgcli.main ERROR - traceback: 'Traceback (most recent call last):\n  File "/usr/lib/python3.13/site-packages/pgcli/main.py", line 758, in connect\n    raise e\n  File "/usr/lib/python3.13/site-packages/pgcli/main.py", line 729, in connect\n    pgexecute = PGExecute(\n        database,\n    ...<6 lines>...\n        **kwargs,\n    )\n  File "/usr/lib/python3.13/site-packages/pgcli/pgexecute.py", line 184, in __init__\n    self.connect(database, user, password, host, port, dsn, **kwargs)\n    ~~~~~~~~~~~~^^^^^^^^^^^^^^^^^^^^^^^^^^^^^^^^^^^^^^^^^^^^^^^^^^^^^\n  File "/usr/lib/python3.13/site-packages/pgcli/pgexecute.py", line 233, in connect\n    conn = psycopg.connect(conn_info)\n  File "/usr/lib/python3.13/site-packages/psycopg/connection.py", line 119, in connect\n    raise last_ex.with_traceback(None)\npsycopg.OperationalError: connection is bad: connection to server on socket "/run/postgresql/.s.PGSQL.5432" failed: No such file or directory\n\tIs the server running locally and accepting connections on that socket?\n'
2025-01-25 12:47:46,256 (171101/MainThread) pgcli.main INFO - No default pager found in environment. Using os default pager
2025-01-25 12:47:46,256 (171101/MainThread) pgcli.main WARNING - import keyring failed: ModuleNotFoundError("No module named 'keyring'").
2025-01-25 12:47:46,258 (171101/MainThread) pgcli.main ERROR - traceback: 'Traceback (most recent call last):\n  File "/usr/lib/python3.13/site-packages/pgcli/main.py", line 758, in connect\n    raise e\n  File "/usr/lib/python3.13/site-packages/pgcli/main.py", line 729, in connect\n    pgexecute = PGExecute(\n        database,\n    ...<6 lines>...\n        **kwargs,\n    )\n  File "/usr/lib/python3.13/site-packages/pgcli/pgexecute.py", line 184, in __init__\n    self.connect(database, user, password, host, port, dsn, **kwargs)\n    ~~~~~~~~~~~~^^^^^^^^^^^^^^^^^^^^^^^^^^^^^^^^^^^^^^^^^^^^^^^^^^^^^\n  File "/usr/lib/python3.13/site-packages/pgcli/pgexecute.py", line 233, in connect\n    conn = psycopg.connect(conn_info)\n  File "/usr/lib/python3.13/site-packages/psycopg/connection.py", line 119, in connect\n    raise last_ex.with_traceback(None)\npsycopg.OperationalError: connection is bad: connection to server on socket "/run/postgresql/.s.PGSQL.5432" failed: No such file or directory\n\tIs the server running locally and accepting connections on that socket?\n'
2025-01-25 12:48:29,354 (171120/MainThread) pgcli.main INFO - No default pager found in environment. Using os default pager
2025-01-25 12:48:29,354 (171120/MainThread) pgcli.main WARNING - import keyring failed: ModuleNotFoundError("No module named 'keyring'").
2025-01-25 13:31:12,995 (171120/MainThread) pgcli.pgexecute ERROR - sql: 'delete * from green_taxi_data', error: SyntaxError('syntax error at or near "*"\nLINE 1: delete * from green_taxi_data\n               ^')
2025-01-25 13:31:13,000 (171120/MainThread) pgcli.pgexecute ERROR - traceback: 'Traceback (most recent call last):\n  File "/usr/lib/python3.13/site-packages/pgcli/pgexecute.py", line 406, in run\n    yield self.execute_normal_sql(sql) + (sql, True, False)\n          ~~~~~~~~~~~~~~~~~~~~~~~^^^^^\n  File "/usr/lib/python3.13/site-packages/pgcli/pgexecute.py", line 460, in execute_normal_sql\n    cur.execute(split_sql)\n    ~~~~~~~~~~~^^^^^^^^^^^\n  File "/usr/lib/python3.13/site-packages/pgcli/pgexecute.py", line 91, in execute\n    super().execute(*args, **kwargs)\n    ~~~~~~~~~~~~~~~^^^^^^^^^^^^^^^^^\n  File "/usr/lib/python3.13/site-packages/psycopg/cursor.py", line 97, in execute\n    raise ex.with_traceback(None)\npsycopg.errors.SyntaxError: syntax error at or near "*"\nLINE 1: delete * from green_taxi_data\n               ^\n'
2025-01-25 13:32:35,679 (171120/MainThread) pgcli.pgexecute ERROR - sql: 'drop yellow_taxi_data', error: SyntaxError('syntax error at or near "yellow_taxi_data"\nLINE 1: drop yellow_taxi_data\n             ^')
2025-01-25 13:32:35,682 (171120/MainThread) pgcli.pgexecute ERROR - traceback: 'Traceback (most recent call last):\n  File "/usr/lib/python3.13/site-packages/pgcli/pgexecute.py", line 406, in run\n    yield self.execute_normal_sql(sql) + (sql, True, False)\n          ~~~~~~~~~~~~~~~~~~~~~~~^^^^^\n  File "/usr/lib/python3.13/site-packages/pgcli/pgexecute.py", line 460, in execute_normal_sql\n    cur.execute(split_sql)\n    ~~~~~~~~~~~^^^^^^^^^^^\n  File "/usr/lib/python3.13/site-packages/pgcli/pgexecute.py", line 91, in execute\n    super().execute(*args, **kwargs)\n    ~~~~~~~~~~~~~~~^^^^^^^^^^^^^^^^^\n  File "/usr/lib/python3.13/site-packages/psycopg/cursor.py", line 97, in execute\n    raise ex.with_traceback(None)\npsycopg.errors.SyntaxError: syntax error at or near "yellow_taxi_data"\nLINE 1: drop yellow_taxi_data\n             ^\n'
2025-01-25 13:43:53,020 (171120/MainThread) pgcli.pgexecute ERROR - sql: 'select count(1) FROM green_taxi_data where lpep_dropoff_datetime >= make_date(2019, 10, 1) and lpep_drop_datetime < make_date(2019, 11, 1) and trip_distance <= 1', error: UndefinedColumn('column "lpep_drop_datetime" does not exist\nLINE 1: ...ep_dropoff_datetime >= make_date(2019, 10, 1) and lpep_drop_...\n                                                             ^\nHINT:  Perhaps you meant to reference the column "green_taxi_data.lpep_dropoff_datetime".')
2025-01-25 13:43:53,020 (171120/MainThread) pgcli.pgexecute ERROR - traceback: 'Traceback (most recent call last):\n  File "/usr/lib/python3.13/site-packages/pgcli/pgexecute.py", line 406, in run\n    yield self.execute_normal_sql(sql) + (sql, True, False)\n          ~~~~~~~~~~~~~~~~~~~~~~~^^^^^\n  File "/usr/lib/python3.13/site-packages/pgcli/pgexecute.py", line 460, in execute_normal_sql\n    cur.execute(split_sql)\n    ~~~~~~~~~~~^^^^^^^^^^^\n  File "/usr/lib/python3.13/site-packages/pgcli/pgexecute.py", line 91, in execute\n    super().execute(*args, **kwargs)\n    ~~~~~~~~~~~~~~~^^^^^^^^^^^^^^^^^\n  File "/usr/lib/python3.13/site-packages/psycopg/cursor.py", line 97, in execute\n    raise ex.with_traceback(None)\npsycopg.errors.UndefinedColumn: column "lpep_drop_datetime" does not exist\nLINE 1: ...ep_dropoff_datetime >= make_date(2019, 10, 1) and lpep_drop_...\n                                                             ^\nHINT:  Perhaps you meant to reference the column "green_taxi_data.lpep_dropoff_datetime".\n'
2025-01-25 13:46:56,158 (171120/MainThread) pgcli.pgexecute ERROR - sql: 'with daily_trip_distance AS (select sum(trip_distance) from green_taxi_data group by DAY(lpep_pickup_datetime), MONTH(lpep_pickup_datetime), YEAR(lpep_pickup_datetime)) select * from daily_trip_distance', error: UndefinedFunction('function day(timestamp without time zone) does not exist\nLINE 1: ... sum(trip_distance) from green_taxi_data group by DAY(lpep_p...\n                                                             ^\nHINT:  No function matches the given name and argument types. You might need to add explicit type casts.')
2025-01-25 13:46:56,159 (171120/MainThread) pgcli.pgexecute ERROR - traceback: 'Traceback (most recent call last):\n  File "/usr/lib/python3.13/site-packages/pgcli/pgexecute.py", line 406, in run\n    yield self.execute_normal_sql(sql) + (sql, True, False)\n          ~~~~~~~~~~~~~~~~~~~~~~~^^^^^\n  File "/usr/lib/python3.13/site-packages/pgcli/pgexecute.py", line 460, in execute_normal_sql\n    cur.execute(split_sql)\n    ~~~~~~~~~~~^^^^^^^^^^^\n  File "/usr/lib/python3.13/site-packages/pgcli/pgexecute.py", line 91, in execute\n    super().execute(*args, **kwargs)\n    ~~~~~~~~~~~~~~~^^^^^^^^^^^^^^^^^\n  File "/usr/lib/python3.13/site-packages/psycopg/cursor.py", line 97, in execute\n    raise ex.with_traceback(None)\npsycopg.errors.UndefinedFunction: function day(timestamp without time zone) does not exist\nLINE 1: ... sum(trip_distance) from green_taxi_data group by DAY(lpep_p...\n                                                             ^\nHINT:  No function matches the given name and argument types. You might need to add explicit type casts.\n'
2025-01-25 13:56:45,649 (171120/MainThread) pgcli.pgexecute ERROR - sql: 'select * from green_taxi_data gtd join zones z on gtd.PULocationID = z.LocationID', error: UndefinedColumn('column gtd.pulocationid does not exist\nLINE 1: select * from green_taxi_data gtd join zones z on gtd.PULoca...\n                                                          ^')
2025-01-25 13:56:45,650 (171120/MainThread) pgcli.pgexecute ERROR - traceback: 'Traceback (most recent call last):\n  File "/usr/lib/python3.13/site-packages/pgcli/pgexecute.py", line 406, in run\n    yield self.execute_normal_sql(sql) + (sql, True, False)\n          ~~~~~~~~~~~~~~~~~~~~~~~^^^^^\n  File "/usr/lib/python3.13/site-packages/pgcli/pgexecute.py", line 460, in execute_normal_sql\n    cur.execute(split_sql)\n    ~~~~~~~~~~~^^^^^^^^^^^\n  File "/usr/lib/python3.13/site-packages/pgcli/pgexecute.py", line 91, in execute\n    super().execute(*args, **kwargs)\n    ~~~~~~~~~~~~~~~^^^^^^^^^^^^^^^^^\n  File "/usr/lib/python3.13/site-packages/psycopg/cursor.py", line 97, in execute\n    raise ex.with_traceback(None)\npsycopg.errors.UndefinedColumn: column gtd.pulocationid does not exist\nLINE 1: select * from green_taxi_data gtd join zones z on gtd.PULoca...\n                                                          ^\n'
2025-01-25 13:57:01,893 (171120/MainThread) pgcli.pgexecute ERROR - sql: 'select PULocationID from green_taxi_data', error: UndefinedColumn('column "pulocationid" does not exist\nLINE 1: select PULocationID from green_taxi_data\n               ^')
2025-01-25 13:57:01,894 (171120/MainThread) pgcli.pgexecute ERROR - traceback: 'Traceback (most recent call last):\n  File "/usr/lib/python3.13/site-packages/pgcli/pgexecute.py", line 406, in run\n    yield self.execute_normal_sql(sql) + (sql, True, False)\n          ~~~~~~~~~~~~~~~~~~~~~~~^^^^^\n  File "/usr/lib/python3.13/site-packages/pgcli/pgexecute.py", line 460, in execute_normal_sql\n    cur.execute(split_sql)\n    ~~~~~~~~~~~^^^^^^^^^^^\n  File "/usr/lib/python3.13/site-packages/pgcli/pgexecute.py", line 91, in execute\n    super().execute(*args, **kwargs)\n    ~~~~~~~~~~~~~~~^^^^^^^^^^^^^^^^^\n  File "/usr/lib/python3.13/site-packages/psycopg/cursor.py", line 97, in execute\n    raise ex.with_traceback(None)\npsycopg.errors.UndefinedColumn: column "pulocationid" does not exist\nLINE 1: select PULocationID from green_taxi_data\n               ^\n'
2025-01-25 13:58:20,899 (171120/MainThread) pgcli.pgexecute ERROR - sql: 'select * from green_taxi_data gtd join zones z on gtd.PULocationID = z.LocationID limit 5', error: UndefinedColumn('column z.locationid does not exist\nLINE 1: ..._taxi_data gtd join zones z on gtd.PULocationID = z.Location...\n                                                             ^\nHINT:  Perhaps you meant to reference the column "z.LocationID".')
2025-01-25 13:58:20,902 (171120/MainThread) pgcli.pgexecute ERROR - traceback: 'Traceback (most recent call last):\n  File "/usr/lib/python3.13/site-packages/pgcli/pgexecute.py", line 406, in run\n    yield self.execute_normal_sql(sql) + (sql, True, False)\n          ~~~~~~~~~~~~~~~~~~~~~~~^^^^^\n  File "/usr/lib/python3.13/site-packages/pgcli/pgexecute.py", line 460, in execute_normal_sql\n    cur.execute(split_sql)\n    ~~~~~~~~~~~^^^^^^^^^^^\n  File "/usr/lib/python3.13/site-packages/pgcli/pgexecute.py", line 91, in execute\n    super().execute(*args, **kwargs)\n    ~~~~~~~~~~~~~~~^^^^^^^^^^^^^^^^^\n  File "/usr/lib/python3.13/site-packages/psycopg/cursor.py", line 97, in execute\n    raise ex.with_traceback(None)\npsycopg.errors.UndefinedColumn: column z.locationid does not exist\nLINE 1: ..._taxi_data gtd join zones z on gtd.PULocationID = z.Location...\n                                                             ^\nHINT:  Perhaps you meant to reference the column "z.LocationID".\n'
2025-01-25 13:58:54,254 (171120/MainThread) pgcli.pgexecute ERROR - sql: 'select * from green_taxi_data gtd join zones z on gtd.PULocationID = z.LocationID limit 5', error: UndefinedColumn('column z.locationid does not exist\nLINE 1: ..._taxi_data gtd join zones z on gtd.PULocationID = z.Location...\n                                                             ^\nHINT:  Perhaps you meant to reference the column "z.LocationID".')
2025-01-25 13:58:54,255 (171120/MainThread) pgcli.pgexecute ERROR - traceback: 'Traceback (most recent call last):\n  File "/usr/lib/python3.13/site-packages/pgcli/pgexecute.py", line 406, in run\n    yield self.execute_normal_sql(sql) + (sql, True, False)\n          ~~~~~~~~~~~~~~~~~~~~~~~^^^^^\n  File "/usr/lib/python3.13/site-packages/pgcli/pgexecute.py", line 460, in execute_normal_sql\n    cur.execute(split_sql)\n    ~~~~~~~~~~~^^^^^^^^^^^\n  File "/usr/lib/python3.13/site-packages/pgcli/pgexecute.py", line 91, in execute\n    super().execute(*args, **kwargs)\n    ~~~~~~~~~~~~~~~^^^^^^^^^^^^^^^^^\n  File "/usr/lib/python3.13/site-packages/psycopg/cursor.py", line 97, in execute\n    raise ex.with_traceback(None)\npsycopg.errors.UndefinedColumn: column z.locationid does not exist\nLINE 1: ..._taxi_data gtd join zones z on gtd.PULocationID = z.Location...\n                                                             ^\nHINT:  Perhaps you meant to reference the column "z.LocationID".\n'
2025-01-25 14:01:49,321 (171120/MainThread) pgcli.pgexecute ERROR - sql: 'select z.LocationID, sum(total_amount) from green_taxi_data gtd join zones z on gtd.PULocationID = z.LocationID where date(lpep_pickup_datetime) = make_date(2019, 10, 18)  limit 3', error: GroupingError('column "z.locationid" must appear in the GROUP BY clause or be used in an aggregate function\nLINE 1: select z.LocationID, sum(total_amount) from green_taxi_data ...\n               ^')
2025-01-25 14:01:49,322 (171120/MainThread) pgcli.pgexecute ERROR - traceback: 'Traceback (most recent call last):\n  File "/usr/lib/python3.13/site-packages/pgcli/pgexecute.py", line 406, in run\n    yield self.execute_normal_sql(sql) + (sql, True, False)\n          ~~~~~~~~~~~~~~~~~~~~~~~^^^^^\n  File "/usr/lib/python3.13/site-packages/pgcli/pgexecute.py", line 460, in execute_normal_sql\n    cur.execute(split_sql)\n    ~~~~~~~~~~~^^^^^^^^^^^\n  File "/usr/lib/python3.13/site-packages/pgcli/pgexecute.py", line 91, in execute\n    super().execute(*args, **kwargs)\n    ~~~~~~~~~~~~~~~^^^^^^^^^^^^^^^^^\n  File "/usr/lib/python3.13/site-packages/psycopg/cursor.py", line 97, in execute\n    raise ex.with_traceback(None)\npsycopg.errors.GroupingError: column "z.locationid" must appear in the GROUP BY clause or be used in an aggregate function\nLINE 1: select z.LocationID, sum(total_amount) from green_taxi_data ...\n               ^\n'
2025-01-25 14:04:48,617 (171120/MainThread) pgcli.pgexecute ERROR - sql: 'select total_amount from green_taxi_date', error: UndefinedTable('relation "green_taxi_date" does not exist\nLINE 1: select total_amount from green_taxi_date\n                                 ^')
2025-01-25 14:04:48,617 (171120/MainThread) pgcli.pgexecute ERROR - traceback: 'Traceback (most recent call last):\n  File "/usr/lib/python3.13/site-packages/pgcli/pgexecute.py", line 406, in run\n    yield self.execute_normal_sql(sql) + (sql, True, False)\n          ~~~~~~~~~~~~~~~~~~~~~~~^^^^^\n  File "/usr/lib/python3.13/site-packages/pgcli/pgexecute.py", line 460, in execute_normal_sql\n    cur.execute(split_sql)\n    ~~~~~~~~~~~^^^^^^^^^^^\n  File "/usr/lib/python3.13/site-packages/pgcli/pgexecute.py", line 91, in execute\n    super().execute(*args, **kwargs)\n    ~~~~~~~~~~~~~~~^^^^^^^^^^^^^^^^^\n  File "/usr/lib/python3.13/site-packages/psycopg/cursor.py", line 97, in execute\n    raise ex.with_traceback(None)\npsycopg.errors.UndefinedTable: relation "green_taxi_date" does not exist\nLINE 1: select total_amount from green_taxi_date\n                                 ^\n'
2025-01-25 14:08:20,539 (171120/MainThread) pgcli.pgexecute ERROR - sql: 'with filtered_taxi_data as (select * from green_taxi_data where date(lpep_pickup_datetime) = make_date(2019, 10, 18) qualify sum(total_amount) over (partition by date(lpep_pickup_datetime)) > 13000 ) select z."Zone", sum(total_amount) from filtered_taxi_data gtd join zones z on gtd.PULocationID = z.LocationID group by 1 order by sum(total_amount) desc limit 3', error: SyntaxError('syntax error at or near "qualify"\nLINE 1: ...e(lpep_pickup_datetime) = make_date(2019, 10, 18) qualify su...\n                                                             ^')
2025-01-25 14:08:20,540 (171120/MainThread) pgcli.pgexecute ERROR - traceback: 'Traceback (most recent call last):\n  File "/usr/lib/python3.13/site-packages/pgcli/pgexecute.py", line 406, in run\n    yield self.execute_normal_sql(sql) + (sql, True, False)\n          ~~~~~~~~~~~~~~~~~~~~~~~^^^^^\n  File "/usr/lib/python3.13/site-packages/pgcli/pgexecute.py", line 460, in execute_normal_sql\n    cur.execute(split_sql)\n    ~~~~~~~~~~~^^^^^^^^^^^\n  File "/usr/lib/python3.13/site-packages/pgcli/pgexecute.py", line 91, in execute\n    super().execute(*args, **kwargs)\n    ~~~~~~~~~~~~~~~^^^^^^^^^^^^^^^^^\n  File "/usr/lib/python3.13/site-packages/psycopg/cursor.py", line 97, in execute\n    raise ex.with_traceback(None)\npsycopg.errors.SyntaxError: syntax error at or near "qualify"\nLINE 1: ...e(lpep_pickup_datetime) = make_date(2019, 10, 18) qualify su...\n                                                             ^\n'
2025-01-25 14:09:53,458 (171120/MainThread) pgcli.pgexecute ERROR - sql: 'with filtered_taxi_data as (select *, sum(total_amount) over (partition by date(lpep_pickup_datetime)) as total_amount_sum from green_taxi_data where date(lpep_pickup_datetime) = make_date(2019, 10, 18)) > 13000 ) select z."Zone", sum(total_amount) from filtered_taxi_data gtd join zones z on gtd.PULocationID = z.LocationID where total_amount_sum > 13000 group by 1 order by sum(total_amount) desc limit 3', error: SyntaxError('syntax error at or near ">"\nLINE 1: ...(lpep_pickup_datetime) = make_date(2019, 10, 18)) > 13000 ) ...\n                                                             ^')
2025-01-25 14:09:53,459 (171120/MainThread) pgcli.pgexecute ERROR - traceback: 'Traceback (most recent call last):\n  File "/usr/lib/python3.13/site-packages/pgcli/pgexecute.py", line 406, in run\n    yield self.execute_normal_sql(sql) + (sql, True, False)\n          ~~~~~~~~~~~~~~~~~~~~~~~^^^^^\n  File "/usr/lib/python3.13/site-packages/pgcli/pgexecute.py", line 460, in execute_normal_sql\n    cur.execute(split_sql)\n    ~~~~~~~~~~~^^^^^^^^^^^\n  File "/usr/lib/python3.13/site-packages/pgcli/pgexecute.py", line 91, in execute\n    super().execute(*args, **kwargs)\n    ~~~~~~~~~~~~~~~^^^^^^^^^^^^^^^^^\n  File "/usr/lib/python3.13/site-packages/psycopg/cursor.py", line 97, in execute\n    raise ex.with_traceback(None)\npsycopg.errors.SyntaxError: syntax error at or near ">"\nLINE 1: ...(lpep_pickup_datetime) = make_date(2019, 10, 18)) > 13000 ) ...\n                                                             ^\n'
2025-01-25 14:10:32,575 (171120/MainThread) pgcli.pgexecute ERROR - sql: 'with filtered_taxi_data as (select *, sum(total_amount) over (partition by date(lpep_pickup_datetime)) as total_amount_sum from green_taxi_data where date(lpep_pickup_datetime) = make_date(2019, 10, 18)) select z."Zone", sum(total_amount), total_amount_sum from filtered_taxi_data gtd join zones z on gtd.PULocationID = z.LocationID where total_amount_sum > 13000 group by 1 order by sum(total_amount) desc limit 3', error: GroupingError('column "gtd.total_amount_sum" must appear in the GROUP BY clause or be used in an aggregate function\nLINE 1: ...019, 10, 18)) select z."Zone", sum(total_amount), total_amou...\n                                                             ^')
2025-01-25 14:10:32,576 (171120/MainThread) pgcli.pgexecute ERROR - traceback: 'Traceback (most recent call last):\n  File "/usr/lib/python3.13/site-packages/pgcli/pgexecute.py", line 406, in run\n    yield self.execute_normal_sql(sql) + (sql, True, False)\n          ~~~~~~~~~~~~~~~~~~~~~~~^^^^^\n  File "/usr/lib/python3.13/site-packages/pgcli/pgexecute.py", line 460, in execute_normal_sql\n    cur.execute(split_sql)\n    ~~~~~~~~~~~^^^^^^^^^^^\n  File "/usr/lib/python3.13/site-packages/pgcli/pgexecute.py", line 91, in execute\n    super().execute(*args, **kwargs)\n    ~~~~~~~~~~~~~~~^^^^^^^^^^^^^^^^^\n  File "/usr/lib/python3.13/site-packages/psycopg/cursor.py", line 97, in execute\n    raise ex.with_traceback(None)\npsycopg.errors.GroupingError: column "gtd.total_amount_sum" must appear in the GROUP BY clause or be used in an aggregate function\nLINE 1: ...019, 10, 18)) select z."Zone", sum(total_amount), total_amou...\n                                                             ^\n'
2025-01-25 14:13:58,088 (171120/MainThread) pgcli.pgexecute ERROR - sql: 'select date(lpep_pickup_datetime), sum(total_amount) over (partition by date(lpep_pickup_datetime)) as total_amount_sum from green_taxi_data where date(lpep_pickup_datetime) = make_date(2019, 10, 18) group by 1', error: GroupingError('column "green_taxi_data.total_amount" must appear in the GROUP BY clause or be used in an aggregate function\nLINE 1: select date(lpep_pickup_datetime), sum(total_amount) over (p...\n                                               ^')
2025-01-25 14:13:58,089 (171120/MainThread) pgcli.pgexecute ERROR - traceback: 'Traceback (most recent call last):\n  File "/usr/lib/python3.13/site-packages/pgcli/pgexecute.py", line 406, in run\n    yield self.execute_normal_sql(sql) + (sql, True, False)\n          ~~~~~~~~~~~~~~~~~~~~~~~^^^^^\n  File "/usr/lib/python3.13/site-packages/pgcli/pgexecute.py", line 460, in execute_normal_sql\n    cur.execute(split_sql)\n    ~~~~~~~~~~~^^^^^^^^^^^\n  File "/usr/lib/python3.13/site-packages/pgcli/pgexecute.py", line 91, in execute\n    super().execute(*args, **kwargs)\n    ~~~~~~~~~~~~~~~^^^^^^^^^^^^^^^^^\n  File "/usr/lib/python3.13/site-packages/psycopg/cursor.py", line 97, in execute\n    raise ex.with_traceback(None)\npsycopg.errors.GroupingError: column "green_taxi_data.total_amount" must appear in the GROUP BY clause or be used in an aggregate function\nLINE 1: select date(lpep_pickup_datetime), sum(total_amount) over (p...\n                                               ^\n'
2025-01-25 14:15:01,239 (171120/MainThread) pgcli.pgexecute ERROR - sql: 'select zone, lpep_pickup_datetime, total_amount from green_taxi_data gtd join zones z on gtd.PULocationID = z.LocationID limit 5', error: UndefinedColumn('column "zone" does not exist\nLINE 1: select zone, lpep_pickup_datetime, total_amount from green_t...\n               ^\nHINT:  Perhaps you meant to reference the column "z.Zone".')
2025-01-25 14:15:01,240 (171120/MainThread) pgcli.pgexecute ERROR - traceback: 'Traceback (most recent call last):\n  File "/usr/lib/python3.13/site-packages/pgcli/pgexecute.py", line 406, in run\n    yield self.execute_normal_sql(sql) + (sql, True, False)\n          ~~~~~~~~~~~~~~~~~~~~~~~^^^^^\n  File "/usr/lib/python3.13/site-packages/pgcli/pgexecute.py", line 460, in execute_normal_sql\n    cur.execute(split_sql)\n    ~~~~~~~~~~~^^^^^^^^^^^\n  File "/usr/lib/python3.13/site-packages/pgcli/pgexecute.py", line 91, in execute\n    super().execute(*args, **kwargs)\n    ~~~~~~~~~~~~~~~^^^^^^^^^^^^^^^^^\n  File "/usr/lib/python3.13/site-packages/psycopg/cursor.py", line 97, in execute\n    raise ex.with_traceback(None)\npsycopg.errors.UndefinedColumn: column "zone" does not exist\nLINE 1: select zone, lpep_pickup_datetime, total_amount from green_t...\n               ^\nHINT:  Perhaps you meant to reference the column "z.Zone".\n'
2025-01-25 14:15:09,860 (171120/MainThread) pgcli.pgexecute ERROR - sql: 'select Zone, lpep_pickup_datetime, total_amount from green_taxi_data gtd join zones z on gtd.PULocationID = z.LocationID limit 5', error: UndefinedColumn('column "zone" does not exist\nLINE 1: select Zone, lpep_pickup_datetime, total_amount from green_t...\n               ^\nHINT:  Perhaps you meant to reference the column "z.Zone".')
2025-01-25 14:15:09,860 (171120/MainThread) pgcli.pgexecute ERROR - traceback: 'Traceback (most recent call last):\n  File "/usr/lib/python3.13/site-packages/pgcli/pgexecute.py", line 406, in run\n    yield self.execute_normal_sql(sql) + (sql, True, False)\n          ~~~~~~~~~~~~~~~~~~~~~~~^^^^^\n  File "/usr/lib/python3.13/site-packages/pgcli/pgexecute.py", line 460, in execute_normal_sql\n    cur.execute(split_sql)\n    ~~~~~~~~~~~^^^^^^^^^^^\n  File "/usr/lib/python3.13/site-packages/pgcli/pgexecute.py", line 91, in execute\n    super().execute(*args, **kwargs)\n    ~~~~~~~~~~~~~~~^^^^^^^^^^^^^^^^^\n  File "/usr/lib/python3.13/site-packages/psycopg/cursor.py", line 97, in execute\n    raise ex.with_traceback(None)\npsycopg.errors.UndefinedColumn: column "zone" does not exist\nLINE 1: select Zone, lpep_pickup_datetime, total_amount from green_t...\n               ^\nHINT:  Perhaps you meant to reference the column "z.Zone".\n'
2025-01-25 14:15:17,247 (171120/MainThread) pgcli.pgexecute ERROR - sql: 'select z.Zone, lpep_pickup_datetime, total_amount from green_taxi_data gtd join zones z on gtd.PULocationID = z.LocationID limit 5', error: UndefinedColumn('column z.zone does not exist\nLINE 1: select z.Zone, lpep_pickup_datetime, total_amount from green...\n               ^\nHINT:  Perhaps you meant to reference the column "z.Zone".')
2025-01-25 14:15:17,248 (171120/MainThread) pgcli.pgexecute ERROR - traceback: 'Traceback (most recent call last):\n  File "/usr/lib/python3.13/site-packages/pgcli/pgexecute.py", line 406, in run\n    yield self.execute_normal_sql(sql) + (sql, True, False)\n          ~~~~~~~~~~~~~~~~~~~~~~~^^^^^\n  File "/usr/lib/python3.13/site-packages/pgcli/pgexecute.py", line 460, in execute_normal_sql\n    cur.execute(split_sql)\n    ~~~~~~~~~~~^^^^^^^^^^^\n  File "/usr/lib/python3.13/site-packages/pgcli/pgexecute.py", line 91, in execute\n    super().execute(*args, **kwargs)\n    ~~~~~~~~~~~~~~~^^^^^^^^^^^^^^^^^\n  File "/usr/lib/python3.13/site-packages/psycopg/cursor.py", line 97, in execute\n    raise ex.with_traceback(None)\npsycopg.errors.UndefinedColumn: column z.zone does not exist\nLINE 1: select z.Zone, lpep_pickup_datetime, total_amount from green...\n               ^\nHINT:  Perhaps you meant to reference the column "z.Zone".\n'
2025-01-25 14:39:19,464 (171120/MainThread) pgcli.pgexecute ERROR - sql: 'select puz.Zone as pick_up_zone, gtd.tip_amount from green_taxi_data gtd join zones puz on gtd.PULocationID = z.LocationID join zones doz on gtd."DOLocationID" = z.LocationID where EXTRACT(YEAR FROM lpep_pickup_datetime) = 2019 and EXTRACT(MONTH FROM lpep_pickup_datetime) = 10 and z.Zone = \'East Harlem North\' order by 1 desc limit 5', error: UndefinedTable('missing FROM-clause entry for table "z"\nLINE 1: ...axi_data gtd join zones puz on gtd.PULocationID = z.Location...\n                                                             ^')
2025-01-25 14:39:19,466 (171120/MainThread) pgcli.pgexecute ERROR - traceback: 'Traceback (most recent call last):\n  File "/usr/lib/python3.13/site-packages/pgcli/pgexecute.py", line 406, in run\n    yield self.execute_normal_sql(sql) + (sql, True, False)\n          ~~~~~~~~~~~~~~~~~~~~~~~^^^^^\n  File "/usr/lib/python3.13/site-packages/pgcli/pgexecute.py", line 460, in execute_normal_sql\n    cur.execute(split_sql)\n    ~~~~~~~~~~~^^^^^^^^^^^\n  File "/usr/lib/python3.13/site-packages/pgcli/pgexecute.py", line 91, in execute\n    super().execute(*args, **kwargs)\n    ~~~~~~~~~~~~~~~^^^^^^^^^^^^^^^^^\n  File "/usr/lib/python3.13/site-packages/psycopg/cursor.py", line 97, in execute\n    raise ex.with_traceback(None)\npsycopg.errors.UndefinedTable: missing FROM-clause entry for table "z"\nLINE 1: ...axi_data gtd join zones puz on gtd.PULocationID = z.Location...\n                                                             ^\n'
2025-01-25 14:39:52,550 (171120/MainThread) pgcli.pgexecute ERROR - sql: 'select puz.Zone as pick_up_zone, gtd.tip_amount from green_taxi_data gtd join zones puz on gtd.PULocationID = z.LocationID join zones doz on gtd."DOLocationID" = z.LocationID where EXTRACT(YEAR FROM lpep_pickup_datetime) = 2019 and EXTRACT(MONTH FROM lpep_pickup_datetime) = 10 and z.Zone = \'East Harlem North\' order by 1 desc limit 5', error: UndefinedTable('missing FROM-clause entry for table "z"\nLINE 1: ...axi_data gtd join zones puz on gtd.PULocationID = z.Location...\n                                                             ^')
2025-01-25 14:39:52,551 (171120/MainThread) pgcli.pgexecute ERROR - traceback: 'Traceback (most recent call last):\n  File "/usr/lib/python3.13/site-packages/pgcli/pgexecute.py", line 406, in run\n    yield self.execute_normal_sql(sql) + (sql, True, False)\n          ~~~~~~~~~~~~~~~~~~~~~~~^^^^^\n  File "/usr/lib/python3.13/site-packages/pgcli/pgexecute.py", line 460, in execute_normal_sql\n    cur.execute(split_sql)\n    ~~~~~~~~~~~^^^^^^^^^^^\n  File "/usr/lib/python3.13/site-packages/pgcli/pgexecute.py", line 91, in execute\n    super().execute(*args, **kwargs)\n    ~~~~~~~~~~~~~~~^^^^^^^^^^^^^^^^^\n  File "/usr/lib/python3.13/site-packages/psycopg/cursor.py", line 97, in execute\n    raise ex.with_traceback(None)\npsycopg.errors.UndefinedTable: missing FROM-clause entry for table "z"\nLINE 1: ...axi_data gtd join zones puz on gtd.PULocationID = z.Location...\n                                                             ^\n'
2025-01-25 14:40:09,498 (171120/MainThread) pgcli.pgexecute ERROR - sql: 'select puz.Zone as pick_up_zone, gtd.tip_amount from green_taxi_data gtd join zones puz on gtd.PULocationID = puz.LocationID join zones doz on gtd."DOLocationID" = doz.LocationID where EXTRACT(YEAR FROM lpep_pickup_datetime) = 2019 and EXTRACT(MONTH FROM lpep_pickup_datetime) = 10 and z.Zone = \'East Harlem North\' order by 1 desc limit 5', error: UndefinedColumn('column gtd.DOLocationID does not exist\nLINE 1: ...d.PULocationID = puz.LocationID join zones doz on gtd."DOLoc...\n                                                             ^')
2025-01-25 14:40:09,498 (171120/MainThread) pgcli.pgexecute ERROR - traceback: 'Traceback (most recent call last):\n  File "/usr/lib/python3.13/site-packages/pgcli/pgexecute.py", line 406, in run\n    yield self.execute_normal_sql(sql) + (sql, True, False)\n          ~~~~~~~~~~~~~~~~~~~~~~~^^^^^\n  File "/usr/lib/python3.13/site-packages/pgcli/pgexecute.py", line 460, in execute_normal_sql\n    cur.execute(split_sql)\n    ~~~~~~~~~~~^^^^^^^^^^^\n  File "/usr/lib/python3.13/site-packages/pgcli/pgexecute.py", line 91, in execute\n    super().execute(*args, **kwargs)\n    ~~~~~~~~~~~~~~~^^^^^^^^^^^^^^^^^\n  File "/usr/lib/python3.13/site-packages/psycopg/cursor.py", line 97, in execute\n    raise ex.with_traceback(None)\npsycopg.errors.UndefinedColumn: column gtd.DOLocationID does not exist\nLINE 1: ...d.PULocationID = puz.LocationID join zones doz on gtd."DOLoc...\n                                                             ^\n'
2025-02-02 10:42:13,366 (15348/MainThread) pgcli.main INFO - No default pager found in environment. Using os default pager
2025-02-02 10:42:13,366 (15348/MainThread) pgcli.main WARNING - import keyring failed: ModuleNotFoundError("No module named 'keyring'").
2025-02-02 10:42:13,369 (15348/MainThread) pgcli.main ERROR - traceback: 'Traceback (most recent call last):\n  File "/usr/lib/python3.13/site-packages/pgcli/main.py", line 758, in connect\n    raise e\n  File "/usr/lib/python3.13/site-packages/pgcli/main.py", line 729, in connect\n    pgexecute = PGExecute(\n        database,\n    ...<6 lines>...\n        **kwargs,\n    )\n  File "/usr/lib/python3.13/site-packages/pgcli/pgexecute.py", line 184, in __init__\n    self.connect(database, user, password, host, port, dsn, **kwargs)\n    ~~~~~~~~~~~~^^^^^^^^^^^^^^^^^^^^^^^^^^^^^^^^^^^^^^^^^^^^^^^^^^^^^\n  File "/usr/lib/python3.13/site-packages/pgcli/pgexecute.py", line 233, in connect\n    conn = psycopg.connect(conn_info)\n  File "/usr/lib/python3.13/site-packages/psycopg/connection.py", line 119, in connect\n    raise last_ex.with_traceback(None)\npsycopg.OperationalError: connection is bad: connection to server on socket "/run/postgresql/.s.PGSQL.5432" failed: No such file or directory\n\tIs the server running locally and accepting connections on that socket?\n'
2025-02-02 10:44:32,536 (16127/MainThread) pgcli.main INFO - No default pager found in environment. Using os default pager
2025-02-02 10:44:32,536 (16127/MainThread) pgcli.main WARNING - import keyring failed: ModuleNotFoundError("No module named 'keyring'").
2025-02-02 10:44:32,539 (16127/MainThread) pgcli.main ERROR - traceback: 'Traceback (most recent call last):\n  File "/usr/lib/python3.13/site-packages/pgcli/main.py", line 758, in connect\n    raise e\n  File "/usr/lib/python3.13/site-packages/pgcli/main.py", line 729, in connect\n    pgexecute = PGExecute(\n        database,\n    ...<6 lines>...\n        **kwargs,\n    )\n  File "/usr/lib/python3.13/site-packages/pgcli/pgexecute.py", line 184, in __init__\n    self.connect(database, user, password, host, port, dsn, **kwargs)\n    ~~~~~~~~~~~~^^^^^^^^^^^^^^^^^^^^^^^^^^^^^^^^^^^^^^^^^^^^^^^^^^^^^\n  File "/usr/lib/python3.13/site-packages/pgcli/pgexecute.py", line 233, in connect\n    conn = psycopg.connect(conn_info)\n  File "/usr/lib/python3.13/site-packages/psycopg/connection.py", line 119, in connect\n    raise last_ex.with_traceback(None)\npsycopg.OperationalError: connection is bad: connection to server on socket "/run/postgresql/.s.PGSQL.5432" failed: No such file or directory\n\tIs the server running locally and accepting connections on that socket?\n'
2025-02-02 10:45:42,068 (16440/MainThread) pgcli.main INFO - No default pager found in environment. Using os default pager
2025-02-02 10:45:42,068 (16440/MainThread) pgcli.main WARNING - import keyring failed: ModuleNotFoundError("No module named 'keyring'").
2025-02-02 10:45:42,070 (16440/MainThread) pgcli.main ERROR - traceback: 'Traceback (most recent call last):\n  File "/usr/lib/python3.13/site-packages/pgcli/main.py", line 758, in connect\n    raise e\n  File "/usr/lib/python3.13/site-packages/pgcli/main.py", line 729, in connect\n    pgexecute = PGExecute(\n        database,\n    ...<6 lines>...\n        **kwargs,\n    )\n  File "/usr/lib/python3.13/site-packages/pgcli/pgexecute.py", line 184, in __init__\n    self.connect(database, user, password, host, port, dsn, **kwargs)\n    ~~~~~~~~~~~~^^^^^^^^^^^^^^^^^^^^^^^^^^^^^^^^^^^^^^^^^^^^^^^^^^^^^\n  File "/usr/lib/python3.13/site-packages/pgcli/pgexecute.py", line 233, in connect\n    conn = psycopg.connect(conn_info)\n  File "/usr/lib/python3.13/site-packages/psycopg/connection.py", line 119, in connect\n    raise last_ex.with_traceback(None)\npsycopg.OperationalError: connection is bad: connection to server on socket "/run/postgresql/.s.PGSQL.5432" failed: No such file or directory\n\tIs the server running locally and accepting connections on that socket?\n'
2025-02-02 10:48:27,430 (17279/MainThread) pgcli.main INFO - No default pager found in environment. Using os default pager
2025-02-02 10:48:27,430 (17279/MainThread) pgcli.main WARNING - import keyring failed: ModuleNotFoundError("No module named 'keyring'").
2025-02-02 13:10:56,918 (3743/MainThread) pgcli.main INFO - No default pager found in environment. Using os default pager
2025-02-02 13:10:56,919 (3743/MainThread) pgcli.main WARNING - import keyring failed: ModuleNotFoundError("No module named 'keyring'").
2025-02-02 13:10:56,926 (3743/MainThread) pgcli.main ERROR - traceback: 'Traceback (most recent call last):\n  File "/usr/lib/python3.13/site-packages/pgcli/main.py", line 758, in connect\n    raise e\n  File "/usr/lib/python3.13/site-packages/pgcli/main.py", line 729, in connect\n    pgexecute = PGExecute(\n        database,\n    ...<6 lines>...\n        **kwargs,\n    )\n  File "/usr/lib/python3.13/site-packages/pgcli/pgexecute.py", line 184, in __init__\n    self.connect(database, user, password, host, port, dsn, **kwargs)\n    ~~~~~~~~~~~~^^^^^^^^^^^^^^^^^^^^^^^^^^^^^^^^^^^^^^^^^^^^^^^^^^^^^\n  File "/usr/lib/python3.13/site-packages/pgcli/pgexecute.py", line 233, in connect\n    conn = psycopg.connect(conn_info)\n  File "/usr/lib/python3.13/site-packages/psycopg/connection.py", line 119, in connect\n    raise last_ex.with_traceback(None)\npsycopg.OperationalError: connection is bad: connection to server on socket "/run/postgresql/.s.PGSQL.5432" failed: No such file or directory\n\tIs the server running locally and accepting connections on that socket?\n'
2025-02-02 13:13:06,530 (4218/MainThread) pgcli.main INFO - No default pager found in environment. Using os default pager
2025-02-02 13:13:06,530 (4218/MainThread) pgcli.main WARNING - import keyring failed: ModuleNotFoundError("No module named 'keyring'").
2025-02-02 13:34:48,728 (9518/MainThread) pgcli.main INFO - No default pager found in environment. Using os default pager
2025-02-02 13:34:48,728 (9518/MainThread) pgcli.main WARNING - import keyring failed: ModuleNotFoundError("No module named 'keyring'").
2025-02-02 13:34:48,733 (9518/MainThread) pgcli.main ERROR - traceback: 'Traceback (most recent call last):\n  File "/usr/lib/python3.13/site-packages/pgcli/main.py", line 758, in connect\n    raise e\n  File "/usr/lib/python3.13/site-packages/pgcli/main.py", line 729, in connect\n    pgexecute = PGExecute(\n        database,\n    ...<6 lines>...\n        **kwargs,\n    )\n  File "/usr/lib/python3.13/site-packages/pgcli/pgexecute.py", line 184, in __init__\n    self.connect(database, user, password, host, port, dsn, **kwargs)\n    ~~~~~~~~~~~~^^^^^^^^^^^^^^^^^^^^^^^^^^^^^^^^^^^^^^^^^^^^^^^^^^^^^\n  File "/usr/lib/python3.13/site-packages/pgcli/pgexecute.py", line 233, in connect\n    conn = psycopg.connect(conn_info)\n  File "/usr/lib/python3.13/site-packages/psycopg/connection.py", line 119, in connect\n    raise last_ex.with_traceback(None)\npsycopg.OperationalError: connection failed: connection to server at "127.0.0.1", port 5432 failed: Connection refused\n\tIs the server running on that host and accepting TCP/IP connections?\n'
2025-02-02 13:35:48,190 (10404/MainThread) pgcli.main INFO - No default pager found in environment. Using os default pager
2025-02-02 13:35:48,191 (10404/MainThread) pgcli.main WARNING - import keyring failed: ModuleNotFoundError("No module named 'keyring'").
2025-02-02 13:51:12,347 (17187/MainThread) pgcli.main INFO - No default pager found in environment. Using os default pager
2025-02-02 13:51:12,347 (17187/MainThread) pgcli.main WARNING - import keyring failed: ModuleNotFoundError("No module named 'keyring'").
2025-02-02 13:51:12,349 (17187/MainThread) pgcli.main ERROR - traceback: 'Traceback (most recent call last):\n  File "/usr/lib/python3.13/site-packages/pgcli/main.py", line 758, in connect\n    raise e\n  File "/usr/lib/python3.13/site-packages/pgcli/main.py", line 729, in connect\n    pgexecute = PGExecute(\n        database,\n    ...<6 lines>...\n        **kwargs,\n    )\n  File "/usr/lib/python3.13/site-packages/pgcli/pgexecute.py", line 184, in __init__\n    self.connect(database, user, password, host, port, dsn, **kwargs)\n    ~~~~~~~~~~~~^^^^^^^^^^^^^^^^^^^^^^^^^^^^^^^^^^^^^^^^^^^^^^^^^^^^^\n  File "/usr/lib/python3.13/site-packages/pgcli/pgexecute.py", line 233, in connect\n    conn = psycopg.connect(conn_info)\n  File "/usr/lib/python3.13/site-packages/psycopg/connection.py", line 119, in connect\n    raise last_ex.with_traceback(None)\npsycopg.OperationalError: connection failed: connection to server at "172.17.0.1", port 5432 failed: Connection refused\n\tIs the server running on that host and accepting TCP/IP connections?\n'
2025-02-02 13:52:43,036 (17454/MainThread) pgcli.main INFO - No default pager found in environment. Using os default pager
2025-02-02 13:52:43,036 (17454/MainThread) pgcli.main WARNING - import keyring failed: ModuleNotFoundError("No module named 'keyring'").
2025-02-02 13:52:43,038 (17454/MainThread) pgcli.main ERROR - traceback: 'Traceback (most recent call last):\n  File "/usr/lib/python3.13/site-packages/pgcli/main.py", line 758, in connect\n    raise e\n  File "/usr/lib/python3.13/site-packages/pgcli/main.py", line 729, in connect\n    pgexecute = PGExecute(\n        database,\n    ...<6 lines>...\n        **kwargs,\n    )\n  File "/usr/lib/python3.13/site-packages/pgcli/pgexecute.py", line 184, in __init__\n    self.connect(database, user, password, host, port, dsn, **kwargs)\n    ~~~~~~~~~~~~^^^^^^^^^^^^^^^^^^^^^^^^^^^^^^^^^^^^^^^^^^^^^^^^^^^^^\n  File "/usr/lib/python3.13/site-packages/pgcli/pgexecute.py", line 233, in connect\n    conn = psycopg.connect(conn_info)\n  File "/usr/lib/python3.13/site-packages/psycopg/connection.py", line 119, in connect\n    raise last_ex.with_traceback(None)\npsycopg.OperationalError: connection failed: connection to server at "127.0.0.1", port 5432 failed: Connection refused\n\tIs the server running on that host and accepting TCP/IP connections?\n'
2025-02-02 13:52:50,561 (17536/MainThread) pgcli.main INFO - No default pager found in environment. Using os default pager
2025-02-02 13:52:50,561 (17536/MainThread) pgcli.main WARNING - import keyring failed: ModuleNotFoundError("No module named 'keyring'").
2025-02-02 13:52:50,565 (17536/MainThread) pgcli.main ERROR - traceback: 'Traceback (most recent call last):\n  File "/usr/lib/python3.13/site-packages/pgcli/main.py", line 758, in connect\n    raise e\n  File "/usr/lib/python3.13/site-packages/pgcli/main.py", line 729, in connect\n    pgexecute = PGExecute(\n        database,\n    ...<6 lines>...\n        **kwargs,\n    )\n  File "/usr/lib/python3.13/site-packages/pgcli/pgexecute.py", line 184, in __init__\n    self.connect(database, user, password, host, port, dsn, **kwargs)\n    ~~~~~~~~~~~~^^^^^^^^^^^^^^^^^^^^^^^^^^^^^^^^^^^^^^^^^^^^^^^^^^^^^\n  File "/usr/lib/python3.13/site-packages/pgcli/pgexecute.py", line 233, in connect\n    conn = psycopg.connect(conn_info)\n  File "/usr/lib/python3.13/site-packages/psycopg/connection.py", line 119, in connect\n    raise last_ex.with_traceback(None)\npsycopg.OperationalError: connection failed: connection to server at "127.0.0.1", port 5432 failed: Connection refused\n\tIs the server running on that host and accepting TCP/IP connections?\n'
2025-02-02 13:53:30,942 (17605/MainThread) pgcli.main INFO - No default pager found in environment. Using os default pager
2025-02-02 13:53:30,942 (17605/MainThread) pgcli.main WARNING - import keyring failed: ModuleNotFoundError("No module named 'keyring'").
2025-02-02 13:53:30,944 (17605/MainThread) pgcli.main ERROR - traceback: 'Traceback (most recent call last):\n  File "/usr/lib/python3.13/site-packages/pgcli/main.py", line 758, in connect\n    raise e\n  File "/usr/lib/python3.13/site-packages/pgcli/main.py", line 729, in connect\n    pgexecute = PGExecute(\n        database,\n    ...<6 lines>...\n        **kwargs,\n    )\n  File "/usr/lib/python3.13/site-packages/pgcli/pgexecute.py", line 184, in __init__\n    self.connect(database, user, password, host, port, dsn, **kwargs)\n    ~~~~~~~~~~~~^^^^^^^^^^^^^^^^^^^^^^^^^^^^^^^^^^^^^^^^^^^^^^^^^^^^^\n  File "/usr/lib/python3.13/site-packages/pgcli/pgexecute.py", line 233, in connect\n    conn = psycopg.connect(conn_info)\n  File "/usr/lib/python3.13/site-packages/psycopg/connection.py", line 119, in connect\n    raise last_ex.with_traceback(None)\npsycopg.OperationalError: connection is bad: connection to server on socket "/run/postgresql/.s.PGSQL.5432" failed: No such file or directory\n\tIs the server running locally and accepting connections on that socket?\n'
2025-02-02 13:54:10,110 (18019/MainThread) pgcli.main INFO - No default pager found in environment. Using os default pager
2025-02-02 13:54:10,111 (18019/MainThread) pgcli.main WARNING - import keyring failed: ModuleNotFoundError("No module named 'keyring'").
2025-02-02 13:56:40,280 (18342/MainThread) pgcli.main INFO - No default pager found in environment. Using os default pager
2025-02-02 13:56:40,280 (18342/MainThread) pgcli.main WARNING - import keyring failed: ModuleNotFoundError("No module named 'keyring'").
2025-02-02 13:59:18,242 (19644/MainThread) pgcli.main INFO - No default pager found in environment. Using os default pager
2025-02-02 13:59:18,242 (19644/MainThread) pgcli.main WARNING - import keyring failed: ModuleNotFoundError("No module named 'keyring'").
2025-02-02 13:59:18,246 (19644/MainThread) pgcli.main ERROR - traceback: 'Traceback (most recent call last):\n  File "/usr/lib/python3.13/site-packages/pgcli/main.py", line 758, in connect\n    raise e\n  File "/usr/lib/python3.13/site-packages/pgcli/main.py", line 729, in connect\n    pgexecute = PGExecute(\n        database,\n    ...<6 lines>...\n        **kwargs,\n    )\n  File "/usr/lib/python3.13/site-packages/pgcli/pgexecute.py", line 184, in __init__\n    self.connect(database, user, password, host, port, dsn, **kwargs)\n    ~~~~~~~~~~~~^^^^^^^^^^^^^^^^^^^^^^^^^^^^^^^^^^^^^^^^^^^^^^^^^^^^^\n  File "/usr/lib/python3.13/site-packages/pgcli/pgexecute.py", line 233, in connect\n    conn = psycopg.connect(conn_info)\n  File "/usr/lib/python3.13/site-packages/psycopg/connection.py", line 119, in connect\n    raise last_ex.with_traceback(None)\npsycopg.OperationalError: connection failed: connection to server at "127.0.0.1", port 5432 failed: Connection refused\n\tIs the server running on that host and accepting TCP/IP connections?\n'
2025-02-02 13:59:26,722 (19682/MainThread) pgcli.main INFO - No default pager found in environment. Using os default pager
2025-02-02 13:59:26,722 (19682/MainThread) pgcli.main WARNING - import keyring failed: ModuleNotFoundError("No module named 'keyring'").
2025-02-02 13:59:26,725 (19682/MainThread) pgcli.main ERROR - traceback: 'Traceback (most recent call last):\n  File "/usr/lib/python3.13/site-packages/pgcli/main.py", line 758, in connect\n    raise e\n  File "/usr/lib/python3.13/site-packages/pgcli/main.py", line 729, in connect\n    pgexecute = PGExecute(\n        database,\n    ...<6 lines>...\n        **kwargs,\n    )\n  File "/usr/lib/python3.13/site-packages/pgcli/pgexecute.py", line 184, in __init__\n    self.connect(database, user, password, host, port, dsn, **kwargs)\n    ~~~~~~~~~~~~^^^^^^^^^^^^^^^^^^^^^^^^^^^^^^^^^^^^^^^^^^^^^^^^^^^^^\n  File "/usr/lib/python3.13/site-packages/pgcli/pgexecute.py", line 233, in connect\n    conn = psycopg.connect(conn_info)\n  File "/usr/lib/python3.13/site-packages/psycopg/connection.py", line 119, in connect\n    raise last_ex.with_traceback(None)\npsycopg.OperationalError: connection failed: connection to server at "0.0.0.0", port 5432 failed: Connection refused\n\tIs the server running on that host and accepting TCP/IP connections?\n'
2025-02-02 14:00:14,691 (19793/MainThread) pgcli.main INFO - No default pager found in environment. Using os default pager
2025-02-02 14:00:14,691 (19793/MainThread) pgcli.main WARNING - import keyring failed: ModuleNotFoundError("No module named 'keyring'").
2025-02-02 14:00:14,696 (19793/MainThread) pgcli.main ERROR - traceback: 'Traceback (most recent call last):\n  File "/usr/lib/python3.13/site-packages/pgcli/main.py", line 758, in connect\n    raise e\n  File "/usr/lib/python3.13/site-packages/pgcli/main.py", line 729, in connect\n    pgexecute = PGExecute(\n        database,\n    ...<6 lines>...\n        **kwargs,\n    )\n  File "/usr/lib/python3.13/site-packages/pgcli/pgexecute.py", line 184, in __init__\n    self.connect(database, user, password, host, port, dsn, **kwargs)\n    ~~~~~~~~~~~~^^^^^^^^^^^^^^^^^^^^^^^^^^^^^^^^^^^^^^^^^^^^^^^^^^^^^\n  File "/usr/lib/python3.13/site-packages/pgcli/pgexecute.py", line 233, in connect\n    conn = psycopg.connect(conn_info)\n  File "/usr/lib/python3.13/site-packages/psycopg/connection.py", line 119, in connect\n    raise last_ex.with_traceback(None)\npsycopg.OperationalError: connection failed: connection to server at "127.0.0.1", port 5432 failed: Connection refused\n\tIs the server running on that host and accepting TCP/IP connections?\n'
2025-02-02 14:22:03,808 (11530/MainThread) pgcli.main INFO - No default pager found in environment. Using os default pager
2025-02-02 14:22:03,808 (11530/MainThread) pgcli.main WARNING - import keyring failed: ModuleNotFoundError("No module named 'keyring'").
2025-02-02 14:22:03,815 (11530/MainThread) pgcli.main ERROR - traceback: 'Traceback (most recent call last):\n  File "/usr/lib/python3.13/site-packages/pgcli/main.py", line 758, in connect\n    raise e\n  File "/usr/lib/python3.13/site-packages/pgcli/main.py", line 729, in connect\n    pgexecute = PGExecute(\n        database,\n    ...<6 lines>...\n        **kwargs,\n    )\n  File "/usr/lib/python3.13/site-packages/pgcli/pgexecute.py", line 184, in __init__\n    self.connect(database, user, password, host, port, dsn, **kwargs)\n    ~~~~~~~~~~~~^^^^^^^^^^^^^^^^^^^^^^^^^^^^^^^^^^^^^^^^^^^^^^^^^^^^^\n  File "/usr/lib/python3.13/site-packages/pgcli/pgexecute.py", line 233, in connect\n    conn = psycopg.connect(conn_info)\n  File "/usr/lib/python3.13/site-packages/psycopg/connection.py", line 119, in connect\n    raise last_ex.with_traceback(None)\npsycopg.OperationalError: connection failed: connection to server at "127.0.0.1", port 5432 failed: Connection refused\n\tIs the server running on that host and accepting TCP/IP connections?\n'
2025-02-02 14:22:14,934 (11569/MainThread) pgcli.main INFO - No default pager found in environment. Using os default pager
2025-02-02 14:22:14,934 (11569/MainThread) pgcli.main WARNING - import keyring failed: ModuleNotFoundError("No module named 'keyring'").
2025-02-02 14:22:14,937 (11569/MainThread) pgcli.main ERROR - traceback: 'Traceback (most recent call last):\n  File "/usr/lib/python3.13/site-packages/pgcli/main.py", line 758, in connect\n    raise e\n  File "/usr/lib/python3.13/site-packages/pgcli/main.py", line 729, in connect\n    pgexecute = PGExecute(\n        database,\n    ...<6 lines>...\n        **kwargs,\n    )\n  File "/usr/lib/python3.13/site-packages/pgcli/pgexecute.py", line 184, in __init__\n    self.connect(database, user, password, host, port, dsn, **kwargs)\n    ~~~~~~~~~~~~^^^^^^^^^^^^^^^^^^^^^^^^^^^^^^^^^^^^^^^^^^^^^^^^^^^^^\n  File "/usr/lib/python3.13/site-packages/pgcli/pgexecute.py", line 233, in connect\n    conn = psycopg.connect(conn_info)\n  File "/usr/lib/python3.13/site-packages/psycopg/connection.py", line 119, in connect\n    raise last_ex.with_traceback(None)\npsycopg.OperationalError: connection failed: connection to server at "0.0.0.0", port 5432 failed: Connection refused\n\tIs the server running on that host and accepting TCP/IP connections?\n'
2025-02-02 14:22:52,574 (11638/MainThread) pgcli.main INFO - No default pager found in environment. Using os default pager
2025-02-02 14:22:52,574 (11638/MainThread) pgcli.main WARNING - import keyring failed: ModuleNotFoundError("No module named 'keyring'").
2025-02-02 14:22:52,577 (11638/MainThread) pgcli.main ERROR - traceback: 'Traceback (most recent call last):\n  File "/usr/lib/python3.13/site-packages/pgcli/main.py", line 758, in connect\n    raise e\n  File "/usr/lib/python3.13/site-packages/pgcli/main.py", line 729, in connect\n    pgexecute = PGExecute(\n        database,\n    ...<6 lines>...\n        **kwargs,\n    )\n  File "/usr/lib/python3.13/site-packages/pgcli/pgexecute.py", line 184, in __init__\n    self.connect(database, user, password, host, port, dsn, **kwargs)\n    ~~~~~~~~~~~~^^^^^^^^^^^^^^^^^^^^^^^^^^^^^^^^^^^^^^^^^^^^^^^^^^^^^\n  File "/usr/lib/python3.13/site-packages/pgcli/pgexecute.py", line 233, in connect\n    conn = psycopg.connect(conn_info)\n  File "/usr/lib/python3.13/site-packages/psycopg/connection.py", line 119, in connect\n    raise last_ex.with_traceback(None)\npsycopg.OperationalError: connection is bad: connection to server on socket "/run/postgresql/.s.PGSQL.5432" failed: No such file or directory\n\tIs the server running locally and accepting connections on that socket?\n'
2025-02-02 14:23:03,161 (11694/MainThread) pgcli.main INFO - No default pager found in environment. Using os default pager
2025-02-02 14:23:03,161 (11694/MainThread) pgcli.main WARNING - import keyring failed: ModuleNotFoundError("No module named 'keyring'").
2025-02-02 14:23:06,829 (11694/MainThread) pgcli.main ERROR - traceback: 'Traceback (most recent call last):\n  File "/usr/lib/python3.13/site-packages/pgcli/main.py", line 758, in connect\n    raise e\n  File "/usr/lib/python3.13/site-packages/pgcli/main.py", line 729, in connect\n    pgexecute = PGExecute(\n        database,\n    ...<6 lines>...\n        **kwargs,\n    )\n  File "/usr/lib/python3.13/site-packages/pgcli/pgexecute.py", line 184, in __init__\n    self.connect(database, user, password, host, port, dsn, **kwargs)\n    ~~~~~~~~~~~~^^^^^^^^^^^^^^^^^^^^^^^^^^^^^^^^^^^^^^^^^^^^^^^^^^^^^\n  File "/usr/lib/python3.13/site-packages/pgcli/pgexecute.py", line 233, in connect\n    conn = psycopg.connect(conn_info)\n  File "/usr/lib/python3.13/site-packages/psycopg/connection.py", line 98, in connect\n    attempts = conninfo_attempts(params)\n  File "/usr/lib/python3.13/site-packages/psycopg/_conninfo_attempts.py", line 50, in conninfo_attempts\n    raise e.OperationalError(str(last_exc))\npsycopg.OperationalError: [Errno -2] Name or service not known\n'
